<?xml version="1.0"?>
<robot name="origins">
  
   <material name="blue">
    <color rgba="0 0 0.8 1"/>
  </material>
  <material name="black">
    <color rgba="0 0 0 1"/>
  </material>
  <material name="white">
    <color rgba="1 1 1 1"/>
  </material>
  <material name="red">
    <color rgba="0.7 0 0 1"/>
  </material>
  

  <link name="lidar_mount">
    <visual>
      <geometry>
        <cylinder length="0.6" radius="0.06"/>
        <material name="red"/>
      </geometry>
    </visual>
  </link>

  <link name="base">
    <visual>
      <geometry>
        <box size="1.0 1.0 0.09"/>
      </geometry>
      <origin xyz="0 0 -0.3"/>
      <material name="white"/>
    </visual>
  </link>
  
  <link name="lidar">
    <visual>
      <geometry>
        <cylinder length="0.15" radius="0.11"/>
      </geometry>
      <origin xyz="0 0 0.3"/>
      <material name="red"/>
    </visual>
  </link>

  <link name="R_wheel">
    <visual>
      <geometry>
        <cylinder length="0.05" radius="0.15"/>
      </geometry>
      <origin xyz="0 0 0" rpy="1.57 0 0"/>
      <material name="blue"/>
    </visual>
  </link>

   <link name="L_wheel">
    <visual>
      <geometry>
        <cylinder length="0.05" radius="0.15"/>
      </geometry>
      <origin xyz="0 0 0" rpy="1.57 0 0"/>
      <material name="blue"/>
    </visual>
  </link>
  
  <link name="r_wheel">
    <visual>
      <geometry>
        <cylinder length="0.05" radius="0.09" />
      </geometry>
      <origin xyz="0 0 0" rpy="1.57 0 0" />
      <material name="blue"/>
    </visual>
  </link>

  <link name="l_wheel">
    <visual>
      <geometry>
        <cylinder length="0.05" radius="0.09" />
      </geometry>
      <origin xyz="0 0 0" rpy="1.57 0 0"/>
      <material name="blue"/>
    </visual>
  </link>

  <joint name="wheelJR" type="continuous">
    	<parent link="base"/>
    	<child link="R_wheel"/>
        <axis xyz="0 1 0"/>
    	<origin xyz="0.35 0.55 -0.345" rpy="0 0 0"/>
	</joint>
  
  <joint name="wheelJL" type="continuous">
    	<parent link="base"/>
    	<child link="L_wheel"/>
        <axis xyz="0 1 0"/>
    	<origin xyz="0.35 -0.55 -0.345" rpy="0 0 0"/>
	</joint>
 
  <joint name="wheelJr" type="continuous">
    	<parent link="base"/>
    	<child link="r_wheel"/>
        <axis xyz="0 1 0"/>
    	<origin xyz="-0.35 0.55 -0.345" rpy="0 0 0"/>
	</joint>
  <joint name="wheelJl" type="continuous">
    	<parent link="base"/>
    	<child link="l_wheel"/>
        <axis xyz="0 1 0"/>
    	<origin xyz="-0.35 -0.55 -0.345" rpy="0 0 0"/>
	</joint>
  
 
  <joint name="lidarmount_base" type="fixed">
    	<parent link="base"/>
    	<child link="lidar_mount"/>
    	<origin xyz="0 0 0" rpy="0 0 0"/>
	</joint>

  <joint name="base_mount" type="fixed">
    	<parent link="base"/>
    	<child link="lidar"/>
    	<origin xyz="0 0 0" rpy="0 0 0"/>
	</joint>
</robot>
